2024-05-13 13:52:30,baseApi(line:59),ERROR|Traceback (most recent call last):
  File "D:\Program Files\Python39\lib\site-packages\urllib3\connection.py", line 174, in _new_conn
    conn = connection.create_connection(
  File "D:\Program Files\Python39\lib\site-packages\urllib3\util\connection.py", line 95, in create_connection
    raise err
  File "D:\Program Files\Python39\lib\site-packages\urllib3\util\connection.py", line 85, in create_connection
    sock.connect(sa)
OSError: [WinError 10065] 套接字操作尝试一个无法连接的主机。

During handling of the above exception, another exception occurred:

Traceback (most recent call last):
  File "D:\Program Files\Python39\lib\site-packages\urllib3\connectionpool.py", line 714, in urlopen
    httplib_response = self._make_request(
  File "D:\Program Files\Python39\lib\site-packages\urllib3\connectionpool.py", line 415, in _make_request
    conn.request(method, url, **httplib_request_kw)
  File "D:\Program Files\Python39\lib\site-packages\urllib3\connection.py", line 244, in request
    super(HTTPConnection, self).request(method, url, body=body, headers=headers)
  File "D:\Program Files\Python39\lib\http\client.py", line 1255, in request
    self._send_request(method, url, body, headers, encode_chunked)
  File "D:\Program Files\Python39\lib\http\client.py", line 1301, in _send_request
    self.endheaders(body, encode_chunked=encode_chunked)
  File "D:\Program Files\Python39\lib\http\client.py", line 1250, in endheaders
    self._send_output(message_body, encode_chunked=encode_chunked)
  File "D:\Program Files\Python39\lib\http\client.py", line 1010, in _send_output
    self.send(msg)
  File "D:\Program Files\Python39\lib\http\client.py", line 950, in send
    self.connect()
  File "D:\Program Files\Python39\lib\site-packages\urllib3\connection.py", line 205, in connect
    conn = self._new_conn()
  File "D:\Program Files\Python39\lib\site-packages\urllib3\connection.py", line 186, in _new_conn
    raise NewConnectionError(
urllib3.exceptions.NewConnectionError: <urllib3.connection.HTTPConnection object at 0x000002916503EB80>: Failed to establish a new connection: [WinError 10065] 套接字操作尝试一个无法连接的主机。

During handling of the above exception, another exception occurred:

Traceback (most recent call last):
  File "D:\Program Files\Python39\lib\site-packages\requests\adapters.py", line 486, in send
    resp = conn.urlopen(
  File "D:\Program Files\Python39\lib\site-packages\urllib3\connectionpool.py", line 798, in urlopen
    retries = retries.increment(
  File "D:\Program Files\Python39\lib\site-packages\urllib3\util\retry.py", line 592, in increment
    raise MaxRetryError(_pool, url, error or ResponseError(cause))
urllib3.exceptions.MaxRetryError: HTTPConnectionPool(host='42.192.62.8', port=8082): Max retries exceeded with url: /account/sLogin (Caused by NewConnectionError('<urllib3.connection.HTTPConnection object at 0x000002916503EB80>: Failed to establish a new connection: [WinError 10065] 套接字操作尝试一个无法连接的主机。'))

During handling of the above exception, another exception occurred:

Traceback (most recent call last):
  File "D:\PythonStudy\python3\松勤课堂\DeliverySystem完整代码\common\baseApi.py", line 46, in request_send
    resp = requests.request(
  File "D:\Program Files\Python39\lib\site-packages\requests\api.py", line 59, in request
    return session.request(method=method, url=url, **kwargs)
  File "D:\Program Files\Python39\lib\site-packages\requests\sessions.py", line 589, in request
    resp = self.send(prep, **send_kwargs)
  File "D:\Program Files\Python39\lib\site-packages\requests\sessions.py", line 703, in send
    r = adapter.send(request, **kwargs)
  File "D:\Program Files\Python39\lib\site-packages\requests\adapters.py", line 519, in send
    raise ConnectionError(e, request=request)
requests.exceptions.ConnectionError: HTTPConnectionPool(host='42.192.62.8', port=8082): Max retries exceeded with url: /account/sLogin (Caused by NewConnectionError('<urllib3.connection.HTTPConnection object at 0x000002916503EB80>: Failed to establish a new connection: [WinError 10065] 套接字操作尝试一个无法连接的主机。'))

